Workbook

Sheet IP_BS Raw
A1: Balance Sheet | C1: Yearly
E2: 2021 | F2: 2022 | G2: 2023 | H2: 2024 | I2: 2025
A3: Trạng thái kiểm toán | C3: Audit Status
A4: Công ty Kiểm toán | C4: Audit Firm
A5: Loại Ý kiến Kiểm toán | C5: Audit Opinion Type
A6: TÀI SẢN NGẮN HẠN | C6: CURRENT ASSETS | E6: 1134580036184 | F6: 623158641225 | G6: 947639699363 | H6: 1305306889451 | I6: 1870935494083
A7: Tiền và tương đương tiền | C7: Cash and cash equivalents | E7: 4321225874 | F7: 26473013864 | G7: 8461339357 | H7: 136236074178 | I7: 288524181242
A8: Tiền | C8: Cash | E8: 4321225874 | F8: 22373013864 | G8: 4261339357 | H8: 125344482100 | I8: 167000000000
A9: Các khoản tương đương tiền | C9: Cash equivalents | F9: 4100000000 | G9: 4200000000 | H9: 10891592078
A10: Giá trị thuần đầu tư ngắn hạn | C10: Short-term investments | E10: 4900000000 | F10: 50000000 | G10: 230000000 | H10: 1230000000 | I10: 164600000000
A11: Đầu tư ngắn hạn | C11: Short-term investments
A12: Dự phòng đầu tư ngắn hạn | C12: Provision for diminution
A13: Đầu tư nắm giữ đến ngày đáo hạn | C13: Held-to-maturity investment | E13: 4900000000 | F13: 50000000 | G13: 230000000 | H13: 1230000000 | I13: 164600000000
A14: Các khoản phải thu | C14: Accounts receivable | E14: 1059557585612 | F14: 541296932112 | G14: 845395421575 | H14: 1101930451740 | I14: 1305199947643
A15: Phải thu khách hàng | C15: Trade accounts receivable | E15: 117379744019 | F15: 161650767393 | G15: 239558303914 | H15: 351157857253 | I15: 539420115084
A16: Trả trước người bán | C16: Prepayments to suppliers | E16: 217954579335 | F16: 82005142464 | G16: 80957663203 | H16: 353377447486 | I16: 369672191130
A17: Phải thu nội bộ | C17: Intercompany receivables
A18: Phải thu về XDCB | C18: Construction contract in progress receivables
A19: Phải thu về cho vay ngắn hạn | C19: Short-term loans receivables | E19: 1915829000 | F19: 164433231206 | G19: 266334265625 | H19: 355269960018
A20: Phải thu khác | C20: Other receivables | E20: 757590749230 | F20: 209178378379 | G20: 340356202385 | H20: 113140517320 | I20: 161724203814
A21: Dự phòng nợ khó đòi | C21: Provision for doubtful debts | E21: -35283315972 | F21: -75970587330 | G21: -81811013552 | H21: -71015330337 | I21: -21679830385
A22: Tài sản thiếu chờ xử lý | C22: Shortage of current assets waiting for solution
A23: Hàng tồn kho, ròng | C23: Inventories, Net | E23: 30723500694 | F23: 15511002401 | G23: 29168608393 | H23: 40804852414 | I23: 97855839839
A24: Hàng tồn kho | C24: Inventories | E24: 96101925885 | F24: 75467022274 | G24: 63724327379 | H24: 40804852414 | I24: 97855839839
A25: Dự phòng giảm giá HTK | C25: Provision for decline in inventories | E25: -65378425191 | F25: -59956019873 | G25: -34555718986 | H25: -34555718986
A26: Tài sản lưu động khác | C26: Other current assets | E26: 35077724004 | F26: 39827692848 | G26: 64384330038 | H26: 25105511119 | I26: 14755525359
A27: Chi phí trả trước ngắn hạn | C27: Short-term prepayments | E27: 17929095329 | F27: 27938305891 | G27: 50416954766 | H27: 15054268237 | I27: 9851906402
A28: Thuế GTGT được khấu trừ | C28: VAT to be claimed | E28: 17043590290 | F28: 11733669810 | G28: 13954750488 | H28: 10019963592 | I28: 4872339667
A29: Phải thu thuế khác | C29: Other taxes receivable | E29: 105038385 | F29: 155717147 | G29: 12624784 | H29: 31279290 | I29: 31279290
A30: Giao dịch mua bán lại trái phiếu chính phủ | C30: Government bonds purchased for resale
A31: Tài sản lưu động khác | C31: Other current assets
A32: TÀI SẢN DÀI HẠN | C32: LONG-TERM ASSETS | E32: 237702799766 | F32: 617819241835 | G32: 912758343006 | H32: 1207562711144 | I32: 925445778563
A33: Phải thu dài hạn | C33: Long-term trade receivables | E33: 42966607789 | F33: 368503496695 | G33: 389469485495 | H33: 477290973579 | I33: 223233334800
A34: Phải thu khách hàng dài hạn | C34: Long-term trade receivables from customers | H34: 24000000000 | I34: 24000000000
A35: Trả trước người bán dài hạn | C35: Long-term prepayments to suppliers
A36: Vốn kinh doanh ở các đơn vị trực thuộc | C36: Paid-in capital in wholly-owned subsidiaries
A37: Phải thu nội bộ dài hạn | C37: Long-term intercompany receivables
A38: Phải thu về cho vay dài hạn | C38: Long-term loans receivables | E38: 39090075288 | F38: 119000000000 | G38: 44329575396 | H38: 10990000000 | I38: 19890000000
A39: Phải thu dài hạn khác | C39: Other long-term receivables | E39: 3876532501 | F39: 249503496695 | G39: 345139910099 | H39: 442300973579 | I39: 203343334800
A40: Dự phòng phải thu dài hạn | C40: Provision for doubtful LT receivable
...

Sheet IP_BS Raw (Q)
A1: Balance Sheet | C1: Yearly
E2: Q1/2023 | F2: Q2/2023 | G2: Q3/2023 | H2: Q4/2023 | I2: Q1/2024 | J2: Q2/2024 | K2: Q3/2024 | L2: Q4/2024 | M2: Q1/2025 | N2: Q2/2025
A3: Trạng thái kiểm toán | C3: Audit Status
A4: Công ty Kiểm toán | C4: Audit Firm
A5: Loại Ý kiến Kiểm toán | C5: Audit Opinion Type
A6: TÀI SẢN NGẮN HẠN | C6: CURRENT ASSETS | E6: 1409037526271 | F6: 1155329892754 | G6: 1241097341198 | H6: 1338882873206 | I6: 1534930595272 | J6: 3551337411765 | K6: 2273841866477 | L6: 1811557308602 | M6: 2184149555149 | N6: 2856221396120
A7: Tiền và tương đương tiền | C7: Cash and cash equivalents | E7: 562194548070 | F7: 330747178714 | G7: 308834851881 | H7: 370506274358 | I7: 556699581545 | J7: 655668705735 | K7: 600764730236 | L7: 546631384396 | M7: 883423559831 | N7: 676759173937
A8: Tiền | C8: Cash | E8: 325223629254 | F8: 150633485436 | G8: 136084851881 | H8: 135606274358 | I8: 384898581545 | J8: 336085705735 | K8: 471309730236 | L8: 340111384396 | M8: 393723559831 | N8: 325290173937
A9: Các khoản tương đương tiền | C9: Cash equivalents | E9: 236970918816 | F9: 180113693278 | G9: 172750000000 | H9: 234900000000 | I9: 171801000000 | J9: 319583000000 | K9: 129455000000 | L9: 206520000000 | M9: 489700000000 | N9: 351469000000
A10: Giá trị thuần đầu tư ngắn hạn | C10: Short-term investments | E10: 111367439500 | F10: 264148000000 | G10: 413826714686 | H10: 425016299943 | I10: 469863293757 | J10: 51883578552 | K10: 968931033587 | L10: 806333297341 | M10: 853380702240 | N10: 1721383996451
A11: Đầu tư ngắn hạn | C11: Short-term investments | E11: 0 | F11: 0 | G11: 0 | H11: 0 | I11: 215461708500 | J11: 29683578552 | K11: 712541033587 | L11: 546648172508 | M11: 692356007368 | N11: 1404542928928
A12: Dự phòng đầu tư ngắn hạn | C12: Provision for diminution | E12: 0 | F12: 0 | G12: 0 | H12: 0 | I12: 0 | J12: 0 | K12: 0 | L12: -26064875167 | M12: -11125305128 | N12: -2308932477
A13: Đầu tư nắm giữ đến ngày đáo hạn | C13: Held-to-maturity investment | E13: 111367439500 | F13: 264148000000 | G13: 413826714686 | H13: 425016299943 | I13: 254401585257 | J13: 22200000000 | K13: 256390000000 | L13: 285750000000 | M13: 172150000000 | N13: 319150000000
A14: Các khoản phải thu | C14: Accounts receivable | E14: 599456379288 | F14: 434425753404 | G14: 431391845888 | H14: 459992517275 | I14: 421918186662 | J14: 2744767483791 | K14: 606625885186 | L14: 354874936762 | M14: 336164556041 | N14: 348420871459
A15: Phải thu khách hàng | C15: Trade accounts receivable | E15: 171444908546 | F15: 204039063759 | G15: 229796518541 | H15: 205263011710 | I15: 206694904252 | J15: 306664694204 | K15: 255299695231 | L15: 236744183566 | M15: 229779044357 | N15: 263793638340
A16: Trả trước người bán | C16: Prepayments to suppliers | E16: 7495345183 | F16: 6851897276 | G16: 12131486755 | H16: 13578690375 | I16: 25025462752 | J16: 22298904863 | K16: 36925090068 | L16: 18808589913 | M16: 26804944326 | N16: 18346837122
A17: Phải thu nội bộ | C17: Intercompany receivables | E17: 0 | F17: 0 | G17: 0 | H17: 0 | I17: 0 | J17: 0 | K17: 0 | L17: 0 | M17: 0 | N17: 0
... A97: Trái phiếu chuyển đổi | C97: Convertible bonds | E97: 0 | F97: 0 | G97: 0 | H97: 0 | I97: 0 | J97: 0 | K97: 0 | L97: 0 | M97: 0 | N97: 0
A98: Cổ phiếu ưu đãi | C98: Preferred shares
A99: Thuế thu nhập hoãn lại phải trả | C99: Deferred income tax liabilities | E99: 30858278235 | F99: 30635575473 | G99: 30635575473 | H99: 30412872712 | I99: 30412872712 | J99: 30190169950 | K99: 30190169950 | L99: 530378777454 | M99: 524109383529 | N99: 517134453438
A100: Dự phòng trợ cấp thôi việc | C100: Provision for severance allowances | E100: 0 | F100: 0 | G100: 0 | H100: 0 | I100: 0 | J100: 0 | K100: 0 | L100: 0 | M100: 0 | N100: 0
A101: Dự phòng các khoản công nợ dài hạn | C101: Provision for long-term liabilities | E101: 1005061631 | F101: 904958500 | G101: 904958500 | H101: 3176036942 | I101: 2827286942 | J101: 2827286942 | K101: 2267636942 | L101: 2529636942 | M101: 2232636942 | N101: 1465836942
A102: Quỹ phát triển khoa học công nghệ | C102: Technology-science development fund | E102: 0 | F102: 0 | G102: 0 | H102: 0 | I102: 0 | J102: 0 | K102: 0 | L102: 0 | M102: 0 | N102: 0
A103: VỐN CHỦ SỞ HỮU | C103: OWNER'S EQUITY | E103: 3041381520419 | F103: 3173978566040 | G103: 3222730828695 | H103: 3296823080450 | I103: 3336799929686 | J103: 4655479522764 | K103: 4598804958115 | L103: 4896115718281 | M103: 5124410473113 | N103: 5070117701416
A104: Vốn và các quỹ | C104: Capital and reserves | E104: 3041381520419 | F104: 3173978566040 | G104: 3222730828695 | H104: 3296823080450 | I104: 3336799929686 | J104: 4655479522764 | K104: 4598804958115 | L104: 4896115718281 | M104: 5124410473113 | N104: 5070117701416
A105: Vốn góp | C105: Paid-in capital | E105: 1212693970000 | F105: 1212693970000 | G105: 1333956420000 | H105: 1333956420000 | I105: 1333956420000 | J105: 2667912840000 | K105: 2867968190000 | L105: 2867968190000 | M105: 2995008190000 | N105: 3743703620000
A106: Cổ phiếu phổ thông | C106: Common shares | E106: 1212693970000 | F106: 1212693970000 | G106: 1333956420000 | H106: 1333956420000 | I106: 1333956420000 | J106: 2667912840000 | K106: 2867968190000 | L106: 2867968190000 | M106: 2995008190000 | N106: 3743703620000
A107: Cổ phiếu ưu đãi | C107: Preferred shares | E107: 0 | F107: 0 | G107: 0 | H107: 0 | I107: 0 | J107: 0 | K107: 0 | L107: 0 | M107: 0 | N107: 0
A108: Thặng dư vốn cổ phần | C108: Share premium | E108: 39403521246 | F108: 39403521246 | G108: 39403521246 | H108: 39403521246 | I108: 39403521246 | J108: 39403521246 | K108: 39497521246 | L108: 39497521246 | M108: 39497521246 | N108: 94000000
A109: Quyền chọn chuyển đổi trái phiếu | C109: Conversion options on convertible bonds | E109: 0 | F109: 0 | G109: 0 | H109: 0 | I109: 0 | J109: 0 | K109: 0 | L109: 0 | M109: 0 | N109: 0
A110: Vốn khác | C110: Owner's other capital | E110: 0 | F110: 1382700000 | G110: 0 | H110: 0 | I110: 1382700000 | J110: 1382700000 | K110: 1382700000 | L110: 1382700000 | M110: 1382700000 | N110: 1382700000
... A127: TỔNG CỘNG NGUỒN VỐN | C127: TOTAL RESOURCES | E127: 4420567058149 | F127: 5140761457358 | G127: 5171270660639 | H127: 5186553390197 | I127: 5334073124051 | J127: 6488631865645 | K127: 7311823905729 | L127: 7795129594538 | M127: 8212295180692 | N127: 8775088048296
A129: Backing test
A130: Tổng tài sản & nguồn vốn | C130: Total Asset or Resources | E130: =(E71-E127) -> 0 | F130: =(F71-F127) -> 0 | G130: =(G71-G127) -> 0 | H130: =(H71-H127) -> 0 | I130: =(I71-I127) -> 0 | J130: =(J71-J127) -> 0 | K130: =(K71-K127) -> 0 | L130: =(L71-L127) -> 0 | ... N130: =(N71-N127) -> 0
A131: Tài sản ngắn hạn | C131: Current asset | E131: =E6-E7-E10-E14-E23-E26 -> 0 | F131: =F6-F7-F10-F14-F23-F26 -> 0 | G131: =G6-G7-G10-G14-G23-G26 -> 0 | H131: =H6-H7-H10-H14-H23-H26 -> 0 | I131: =I6-I7-I10-I14-I23-I26 -> 0 | J131: =J6-J7-J10-J14-J23-J26 -> 0 | K131: =K6-K7-K10-K14-K23-K26 -> 0 | L131: =L6-L7-L10-L14-L23-L26 -> 0 | ... N131: =N6-N7-N10-N14-N23-N26 -> 0
A132: Tài sản dài hạn | C132: Non-Current asset | E132: =E32-E33-E41-E52-E55-E58-E64-E65 -> 0 | F132: =F32-F33-F41-F52-F55-F58-F64-F65 -> 0 | G132: =G32-G33-G41-G52-G55-G58-G64-G65 -> 0 | H132: =H32-H33-H41-H52-H55-H58-H64-H65 -> 0 | I132: =I32-I33-I41-I52-I55-I58-I64-I65 -> 0 | J132: =J32-J33-J41-J52-J55-J58-J64-J65 -> 0 | K132: =K32-K33-K41-K52-K55-K58-K64-K65 -> 0 | L132: =L32-L33-L41-L52-L55-L58-L64-L65 -> 0 | ... N132: =N32-N33-N41-N52-N55-N58-N64-N65 -> 0
A133: Tổng tài sản & nguồn vốn | C133: Total asset | E133: =E71-E32-E6 -> 0 | F133: =F71-F32-F6 -> 0 | G133: =G71-G32-G6 -> 0 | H133: =H71-H32-H6 -> 0 | I133: =I71-I32-I6 -> 0 | J133: =J71-J32-J6 -> 0 | K133: =K71-K32-K6 -> 0 | L133: =L71-L32-L6 -> 0 | ... N133: =N71-N32-N6 -> 0
A134: Nguồn vốn ngắn hạn | C134: Current liabilities | E134: =E73-SUM(E74:E87) -> 0 | F134: =F73-SUM(F74:F87) -> 0 | G134: =G73-SUM(G74:G87) -> 0 | H134: =H73-SUM(H74:H87) -> 0 | I134: =I73-SUM(I74:I87) -> 0 | J134: =J73-SUM(J74:J87) -> 0 | K134: =K73-SUM(K74:K87) -> 0 | L134: =L73-SUM(L74:L87) -> 0 | ... N134: =N73-SUM(N74:N87) -> 0
A135: Nguồn vốn dài hạn | C135: Non-Current liabilities | E135: =E88-SUM(E89:E102) -> 0 | F135: =F88-SUM(F89:F102) -> 0 | G135: =G88-SUM(G89:G102) -> 0 | H135: =H88-SUM(H89:H102) -> 0 | I135: =I88-SUM(I89:I102) -> 0 | J135: =J88-SUM(J89:J102) -> 0 | K135: =K88-SUM(K89:K102) -> 0 | L135: =L88-SUM(L89:L102) -> 0 | ... N135: =N88-SUM(N89:N102) -> 0
A136: Tổng nguồn vốn | C136: Total Liabilities | E136: =E72-E73-E88 -> 0 | F136: =F72-F73-F88 -> 0 | G136: =G72-G73-G88 -> 0 | H136: =H72-H73-H88 -> 0 | I136: =I72-I73-I88 -> 0 | J136: =J72-J73-J88 -> 0 | K136: =K72-K73-K88 -> 0 | L136: =L72-L73-L88 -> 0 | ... N136: =N72-N73-N88 -> 0

Sheet IP_IS Raw
A1: Income Statement | C1: Yearly
E2: ='IP_BS Raw'!E2 -> 2021 | F2: ='IP_BS Raw'!F2 -> 2022 | G2: ='IP_BS Raw'!G2 -> 2023 | H2: ='IP_BS Raw'!H2 -> 2024 | I2: ='IP_BS Raw'!I2 -> 2025
A3: Trạng thái kiểm toán | C3: Audit Status
A4: Công ty Kiểm toán | C4: Audit Firm
A5: Loại Ý kiến Kiểm toán | C5: Audit Opinion Type
A6: Doanh thu bán hàng và cung cấp dịch vụ | C6: Sales | E6: 1082183356214 | F6: 317854901716 | G6: 414366625633 | H6: 1026485549969 | I6: 1639453759799
A7: Các khoản giảm trừ doanh thu | C7: Sales deductions | E7: -2675562836 | F7: -3730595402 | G7: -2699840733 | H7: -390681797 | I7: -390681797
A8: Doanh thu thuần | C8: Net sales | E8: 1079507793378 | F8: 314124306314 | G8: 411666784900 | H8: 1026094868172 | I8: 1639063078002
A9: Giá vốn hàng bán | C9: Cost of sales | E9: -1045382703416 | F9: -209645620562 | G9: -296480952992 | H9: -855243703997 | I9: -1424028369399
A10: Lợi nhuận gộp về bán hàng và cung cấp dịch vụ | C10: Gross Profit | E10: 34125089962 | F10: 104478685752 | G10: 115185831908 | H10: 170851164175 | I10: 215034708603
A11: Doanh thu hoạt động tài chính | C11: Financial income | E11: 423849348595 | F11: 47340388199 | G11: 43586401680 | H11: 191906506913 | I11: 120349183176
A12: Chi phí tài chính | C12: Financial expenses | E12: -28037984463 | F12: -9021747176 | G12: -23482415579 | H12: -51108323960 | I12: -27197709414
A13: Trong đó: Chi phí lãi vay | C13: In which: interest expenses | E13: -21801000846 | F13: -6906877175 | G13: -21505000199 | H13: -28208427529 | I13: -25900554619
A14: Lãi/(lỗ) từ công ty liên doanh | C14: Gain/(loss) from joint ventures | E14: 436847500 | F14: 505897455 | G14: -4853955053 | H14: -15223546244 | I14: -1456928964
A15: Chi phí bán hàng | C15: Selling expenses | E15: -86766850424 | F15: -20658752305 | G15: -14260496293 | H15: -26239808550 | I15: -39335239608
A16: Chi phí quản lý doanh nghiệp | C16: General and admin expenses | E16: -211115902487 | F16: -93384172422 | G16: -66900478155 | H16: -151633232794 | I16: -167762629718
A17: Lãi/(lỗ) từ hoạt động kinh doanh | C17: Operating profit/(loss) | E17: 132490548683 | F17: 29260299503 | G17: 49274888508 | H17: 118552759540 | I17: 99631384075
... A20: Chi phí khác | C20: Other expenses | E20: -34656844781 | F20: -19441769061 | G20: -22149929089 | H20: -9003540240 | I20: -5455043465
A21: Lãi/(lỗ) từ công ty liên doanh | C21: Income from investments in other entities
A22: Lãi/(lỗ) ròng trước thuế | C22: Net accounting profit/(loss) before tax | E22: 98316716307 | F22: 28915008361 | G22: 28924117934 | H22: 110622543863 | I22: 94679495741
A23: Chi phí thuế thu nhập doanh nghiệp | C23: Corporate income tax expenses | E23: -68326484945 | F23: -4024148047 | G23: -2405158607 | H23: 11951746732 | I23: -17278295298
A24: Thuế thu nhập doanh nghiệp – hiện thời | C24: Business income tax - current | E24: -38377310844 | F24: -6456274449 | G24: 1545560455 | H24: -12081916503 | I24: -7059602748
A25: Thuế thu nhập doanh nghiệp – hoãn lại | C25: Business income tax - deferred | E25: -29949174101 | F25: 2432126402 | G25: -3950719062 | H25: 24033663235 | I25: -10218692550
A26: Lãi/(lỗ) thuần sau thuế | C26: Net profit/(loss) after tax | E26: 29990231362 | F26: 24890860314 | G26: 26518959327 | H26: 122574290595 | I26: 77401200443
A27: Lợi ích của cổ đông thiểu số | C27: Minority interests | E27: 140197129432 | F27: 13986873201 | G27: -339748836 | H27: -3133772972 | I27: 839269032
A28: Lợi nhuận của Cổ đông của Công ty mẹ | C28: Attributable to parent company | E28: 19793101930 | F28: 10903987113 | G28: 26858708163 | H28: 125708063567 | I28: 76561931411
A29: Lãi cơ bản trên cổ phiếu (VND) | C29: EPS basic (VND) | E29: =E28/(IPc_Others!$G$50*1000000) -> 103.19547 | F29: =F28/(IPc_Others!$G$50*1000000) -> 56.850216 | G29: =G28/(IPc_Others!$G$50*1000000) -> 140.03349 | H29: =H28/(IPc_Others!$G$50*1000000) -> 655.40526 | I29: =I28/(IPc_Others!$G$50*1000000) -> 399.17163
A30: Lãi trên cổ phiếu pha loãng (VND) | C30: EPS diluted (VND) | E30: =E29 -> 103.19547 | F30: =F29 -> 56.850216 | G30: =G29 -> 140.03349 | H30: =H29 -> 655.40526 | I30: =I29 -> 399.17163
A32: Backing test
A33: Lợi nhuận ròng | C33: Gross profit | E33: =E6+E7+E9-E10 -> 0 | F33: =F6+F7+F9-F10 -> 0 | G33: =G6+G7+G9-G10 -> 0 | H33: =H6+H7+H9-H10 -> 0 | I33: =I6+I7+I9-I10 -> 0
A34: Lợi nhuận khác | C34: Other gain | E34: =E18-E19-E20 -> 0 | F34: =F18-F19-F20 -> 0 | G34: =G18-G19-G20 -> 0 | H34: =H18-H19-H20 -> 0 | I34: =I18-I19-I20 -> 0
A35: Lợi nhuận trước thuế | C35: Earning before tax | E35: =E10+E11+E14+E15+E16+E18+E12-E22 -> 0 | F35: =F10+F11+F14+F15+F16+F18+F12-F22 -> 0 | G35: =G10+G11+G14+G15+G16+G18+G12-G22 -> 0 | H35: =H10+H11+H14+H15+H16+H18+H12-H22 -> 0 | I35: =I10+I11+I14+I15+I16+I18+I12-I22 -> 0
A36: Chi phí thuế TNDN | C36: Tax expenses | E36: =E24+E25-E23 -> 0 | F36: =F24+F25-F23 -> 0 | G36: =G24+G25-G23 -> 0 | H36: =H24+H25-H23 -> 0 | I36: =I24+I25-I23 -> 0
A37: Lợi nhuận sau thuế | C37: Eearning after tax | E37: =E22+E23-E26 -> 0 | F37: =F22+F23-F26 -> 0 | G37: =G22+G23-G26 -> 0 | H37: =H22+H23-H26 -> 0 | I37: =I22+I23-I26 -> 0

Sheet IP_CF Raw
A1: Cashflow statement | C1: Yearly
E2: ='IP_BS Raw'!E2 -> 2021 | F2: ='IP_BS Raw'!F2 -> 2022 | G2: ='IP_BS Raw'!G2 -> 2023 | H2: ='IP_BS Raw'!H2 -> 2024 | I2: ='IP_BS Raw'!I2 -> 2025
A3: Trạng thái kiểm toán | C3: Audit Status
A4: Công ty Kiểm toán | C4: Audit Firm
A5: Loại Ý kiến Kiểm toán | C5: Audit Opinion Type
A6: Lợi nhuận/(lỗ) trước thuế | C6: Net profit/(loss) before tax | E6: 98316716307 | F6: 28915008361 | G6: 28924117934 | H6: 110622543863 | I6: 94679495741
A7: Khấu hao TSCĐ, BĐSĐT và phân bổ lợi thế thương mại | C7: Depreciation, amortization and goodwill amortization | E7: 60873843139 | F7: 11001224837 | G7: 12939753078 | H7: 54824557578 | I7: 83639088776
A8: Chi phí dự phòng | C8: Provisions | E8: 52061632930 | F8: 31178258773 | G8: -18008135174 | H8: 16612904416 | I8: 4165257188
A9: Lãi/lỗ chênh lệch tỷ giá hối đoái do đánh giá lại các khoản mục tiền tệ có gốc ngoại tệ | C9: Unrealized foreign exchange gain/(loss) | E9: 158090446 | F9: 28453361
A10: Lãi/(lỗ) từ thanh lý tài sản cố định | C10: Profit/loss from liquidating fixed assets
A11: (Lãi)/lỗ từ hoạt động đầu tư | C11: Profit/loss from investing activities | E11: -417635142186 | F11: -53646900130 | G11: -27299492204 | H11: -155697273093 | I11: -115880067890
A12: Chi phí lãi vay | C12: Interest expense | E12: 21801000846 | F12: 6906877175 | G12: 21505000199 | H12: 28208427529 | I12: 25900554619
A13: Thu lãi và cổ tức | C13: Interest income and dividend
A14: Các khoản điều chỉnh khác | C14: Other adjustments
A15: Lợi nhuận/(lỗ) từ hoạt động kinh doanh trước những thay đổi vốn lưu động | C15: Operating profit/(loss) before changes in Working Capital | E15: -184423858518 | F15: 24382922377 | G15: 18061243833 | H15: 54571160293 | I15: 92504328434
A16: (Tăng)/giảm các khoản phải thu | C16: (Increase)/decrease in receivables | E16: 57022448497 | F16: -152533901863 | G16: -228497578408 | H16: -84686670798 | I16: -22437035213
A17: (Tăng)/giảm hàng tồn kho | C17: (Increase)/decrease in inventories | E17: 33631958809 | F17: 41310624943 | G17: 11742694895 | H17: -57188071887 | I17: -61641565169
A18: Tăng/(giảm) các khoản phải trả | C18: Increase/(decrease) in payables | E18: -84795032317 | F18: -48903797346 | G18: 59812819534 | H18: 419591062933 | I18: 22306828509
A19: (Tăng)/giảm chi phí trả trước | C19: (Increase)/decrease in prepaid expenses | E19: 114913464323 | F19: -6095619097 | G19: -20742237026 | H19: 43291436246 | I19: 21618297007
A20: (Tăng)/giảm chứng khoán kinh doanh | C20: (Increase)/decrease in trading securities
A21: Tiền lãi vay đã trả | C21: Interest paid | E21: -12842860526 | F21: -12387461394 | G21: -21496776942 | H21: -16714808252 | I21: -36916434814
A22: Thuế thu nhập doanh nghiệp đã nộp | C22: Corporate Income Tax paid | E22: -11906493786 | F22: -11091647373 | G22: -11349753635 | H22: -1436256929 | I22: -8068991896
A23: Tiền thu khác từ hoạt động kinh doanh | C23: Other receipts from operating activities
A24: Tiền chi khác cho hoạt động kinh doanh | C24: Other payments on operating activities
A25: Lưu chuyển tiền tệ ròng từ các hoạt động sản xuất kinh doanh | C25: Net cash inflows/(outflows) from operating activities | E25: -88400373518 | F25: -165318879753 | G25: -192469587749 | H25: 357427851606 | I25: 7365426858
A26: Lưu chuyển tiền thuần từ hoạt động đầu tư | C26: Net cash inflows/(outflows) from investing activities | E26: 11187918086 | F26: 293110077155 | G26: -397144764339 | H26: -613628111128 | I26: -192800335481
A27: Tiền chi để mua sắm, xây dựng TSCĐ và các tài sản dài hạn khác | C27: Purchases of fixed assets and other long term assets | E27: -2911894836 | F27: -262090909 | G27: -85145283539 | H27: -552939817718 | I27: -98219383903
A28: Tiền thu từ thanh lý, nhượng bán TSCĐ và các tài sản dài hạn khác | C28: Proceeds from disposal of fixed assets | E28: 386363636 | F28: 9922527548 | G28: 1818413608 | I28: 5000000000
A29: Tiền chi cho vay, mua các công cụ nợ của đơn vị khác | C29: Loans granted, purchases of debt instruments | E29: -1360000000 | F29: -201466970449 | G29: -146568497700 | H29: -235919838301 | I29: -824373768000
A30: Tiền thu hồi cho vay, bán lại các công cụ nợ của đơn vị khác | C30: Collection of loans, proceeds from sales of debts instruments | E30: 17850000000 | F30: 63856855073 | G30: 119157887885 | H30: 164175766640 | I30: 625589460018
A31: Tiền chi đầu tư góp vốn vào đơn vị khác | C31: Investments in other entities | E31: -10699782467 | F31: -62822640694 | G31: -343361250000 | H31: -205721247708 | I31: -65678431605
A32: Tiền thu hồi đầu tư góp vốn vào đơn vị khác | C32: Proceeds from divestment in other entities | E32: 6624547167 | F32: 438675501792 | G32: 37231370000 | H32: 204627695591 | I32: 118927369388
A33: Tiền thu lãi cho vay, cổ tức và lợi nhuận được chia | C33: Dividends and interest received | E33: 1298684586 | F33: 45206894794 | G33: 19722595407 | H33: 12149330368 | I33: 45954418621
A34: Lưu chuyển tiền thuần từ hoạt động tài chính | C34: Net cash inflows/(outflows) from financing activities | E34: 45121186034 | F34: -105639409412 | G34: 571602677581 | H34: 383974994343 | I34: 337710824236
A35: Tiền thu từ phát hành cổ phiếu, nhận vốn góp của chủ sở hữu | C35: Proceeds from issue of shares | G35: 450000000000 | H35: 1767608500 | I35: 548175451265
A36: Tiền chi trả vốn góp cho các chủ sở hữu, mua lại cổ phiếu của doanh nghiệp đã phát hành | C36: Payments for share returns and repurchases
A37: Tiền thu được các khoản đi vay | C37: Proceeds from loans | E37: 230230900461 | F37: 132137409754 | G37: 564918510949 | H37: 634594718729 | I37: 492421816680
A38: Tiền trả nợ gốc vay | C38: Repayment of loans | E38: -185109714427 | F38: -237776819166 | G38: -443315833368 | H38: -252387332886 | I38: -701603005309
A39: Tiền trả nợ gốc thuê tài chính | C39: Finance lease principal payments
A40: Cổ tức, lợi nhuận đã trả cho chủ sở hữu | C40: Dividends paid | I40: -1283438400
...

Sheet IP_Notes Raw
A1: Financial Notes | C1: Yearly
E2: ='IP_BS Raw'!E2 -> 2021 | F2: ='IP_BS Raw'!F2 -> 2022 | G2: ='IP_BS Raw'!G2 -> 2023 | H2: ='IP_BS Raw'!H2 -> 2024 | I2: ='IP_BS Raw'!I2 -> 2025
A3: Trạng thái kiểm toán | C3: Audit Status
A4: Công ty Kiểm toán | C4: Audit Firm | E4: PWC | F4: PWC | G4: PWC | H4: PWC | I4: PWC
A5: Loại Ý kiến Kiểm toán | C5: Audit Opinion Type
A6: Tiền và tương đương tiền | C6: Cash and cash equivalents | E6: =SUM(E7:E10) -> 1013594183927 | F6: =SUM(F7:F10) -> 360383344706 | G6: =SUM(G7:G10) -> 370506274358 | H6: =SUM(H7:H10) -> 546631384396
A7: Tiền mặt | C7: Cash on hand | E7: 3244275331 | F7: 1920102424 | G7: 2716321651 | H7: 2254810590
A8: Tiền gửi Ngân hàng | C8: Cash in banks | E8: 648427921167 | F8: 78670488857 | G8: 132889952707 | H8: 337856573806
A9: Tiền đang chuyển | C9: Cash in transit
A10: Tiền và tương đương tiền | C10: Cash equivalents | E10: 361921987429 | F10: 279792753425 | G10: 234900000000 | H10: 206520000000
A11: Đầu tư tài chính NH | C11: Short-term investments | E11: =SUM(E12:E17) -> 605103106257 | F11: =SUM(F12:F17) -> 726047961971 | G11: =SUM(G12:G17) -> 1895233763147 | H11: =SUM(H12:H17) -> 1565695561055
A12: Chứng khoán đầu tư ngắn hạn | C12: Short-term securities investments | E12: 0 | F12: 0 | G12: 0 | H12: 546648172508
A13: Đầu tư nắm giữ đến ngày đáo hạn | C13: Held-to-maturity investment | E13: 98700000000 | F13: 239367439500 | G13: 425016299943 | H13: 285750000000
A14: Đầu tư ngắn hạn | C14: Short-term | E14: 0 | F14: 0 | G14: 0 | H14: 0
A15: Đầu tư dài hạn | C15: Long-term | E15: 506248106257 | F15: 486525522471 | G15: 1470062463204 | H15: 759207263714
A16: Đầu tư góp vốn vào đơn vị khác | C16: Other short-term investments | E16: 155000000 | F16: 155000000 | G16: 155000000 | H16: 155000000
A17: Dự phòng giảm giá ĐTNH | C17: Provision for diminution in value of short-term investments | E17: 0 | F17: 0 | G17: 0 | H17: -26064875167
A18: Phải thu ngắn hạn khác | C18: Other Receivables | E18: =SUM(E19:E22) -> 230385593342 | F18: =SUM(F19:F22) -> 552878196157 | G18: =SUM(G19:G22) -> 452823464628 | H18: =SUM(H19:H22) -> 339817693240
A19: Phải thu ngắn hạn của khách hàng | C19: Receivables from customers | E19: 210870194878 | F19: 188497724901 | G19: 205263011710 | H19: 236744183566
A20: Phải thu về cổ tức và lợi nhuận được chia | C20: Interest income | E20: 0 | F20: 0 | G20: 0 | H20: 0
A21: Phải thu người lao động | C21: Receivable from employees | E21: 0 | F21: 0 | G21: 0 | H21: 0
A22: Phải thu khác | C22: Other receivables | E22: 19515398464 | F22: 364380471256 | G22: 247560452918 | H22: 103073509674
A23: Hàng tồn kho | C23: INVENTORIES | E23: =SUM(E24:E32) -> 21111762403 | F23: =SUM(F24:F32) -> 28028085828 | G23: =SUM(G24:G32) -> 29065056002 | H23: =SUM(H24:H32) -> 47470252892
A24: Hàng mua đang đi đường | C24: Goods in transit
A25: Nguyên liệu, vật liệu | C25: Raw materials | E25: 1625309134 | F25: 1213108434 | G25: 3078477109 | H25: 4645504999
A26: Công cụ, dụng cụ | C26: Tools and supplies | E26: 18206378530 | F26: 26814977394 | G26: 25921243401 | H26: 40545685394
A27: Chi phí SX, KD dở dang | C27: Work in progress
A28: Thành phẩm | C28: Finished goods
A29: Hàng hóa | C29: Merchandise inventories | E29: 1280074739 | G29: 65335492 | H29: 2279062499
A30: Hàng gửi đi bán | C30: Goods on consignment
A31: Hàng hoá kho bảo thuế | C31: Goods in bonded warehouses
A32: Hàng hoá bất động sản | C32: Property
A33: Tài sản ngắn hạn khác | C33: Other current assets | E33: =SUM(E34:E37) -> 76753394195 | F33: =SUM(F34:F37) -> 43834422724 | G33: =SUM(G34:G37) -> 57164184694 | H33: =SUM(H34:H37) -> 56247437211
A34: Tạm ứng | C34: Advances | E34: 22926052350 | F34: 43834422724 | G34: 20161906312 | H34: =17693351014 -> 17693351014
A35: Tài sản thiếu chờ xử lý | C35: Lack of assets awaiting handling
A36: Cầm cố, ký quỹ, ký cược NH | C36: Short-term deposits or collateral
A37: Khác | C37: Other | E37: =52585960594+1241381251 -> 53827341845 | G37: =35389709327+1612569055 -> 37002278382 | H37: =35639643041+2914443156 -> 38554086197
A38: Phải thu dài hạn khác | C38: Other long-term receivables | E38: =SUM(E39:E42) -> 2333534000 | F38: =SUM(F39:F42) -> 827194723552 | G38: =SUM(G39:G42) -> 827194723552 | H38: =SUM(H39:H42) -> 3624576352
A39: Ký quỹ, ký cược dài hạn | C39: Long-term deposits or collateral
A40: Các khoản tiền nhận ủy thác | C40: Sums received in Trust
...

Sheet IPc_Others
B1: Others Data | C1: YEG VN Equity | D1: =DATE(D2,12,31) -> 44561 | E1: =DATE(E2,12,31) -> 44926 | F1: =DATE(F2,12,29) -> 45289 | G1: =DATE(G2,12,31) -> 45657 | H1: =TODAY()-1 -> 46137 | I1: 12 | J1: 13 | K1: 14 | L1: 15 | M1: 16 | N1: 17 | Q1: Cơ cấu sở hữu & công ty con — YEG
C2: Fields (If Any) | D2: ='IP_BS Raw'!E2 -> 2021 | E2: ='IP_BS Raw'!F2 -> 2022 | F2: ='IP_BS Raw'!G2 -> 2023 | G2: ='IP_BS Raw'!H2 -> 2024 | H2: ='IP_BS Raw'!I2 -> 2025 | I2: =H2+1 -> 2026 | J2: =I2+1 -> 2027 | K2: =J2+1 -> 2028 | L2: =K2+1 -> 2029 | M2: =L2+1 -> 2030 | N2: =M2+1 -> 2031
B3: 1. Market Data | Q3: 1. Cơ cấu sở hữu (Top shareholders)
B4: Market Price (VND) | C4: PX_LAST | D4: 17070 | E4: 13470 | F4: 14160 | G4: 12340 | H4: 9990 | Q4: Cổ đông | R4: Tỷ lệ (%)
B5: 52-Week high (VND) | C5: HIGH_52WEEK | Q5: PYN Elite Fund (Non-Ucits) | R5: 0.0894
B6: 52-Week low (VND) | C6: LOW_52WEEK | Q6: Lê Phương Thảo | R6: 0.0576
B7: 6M avg. daily turnover (VND bn) | C7: 180_DAY_AVERAGE_TURNOVER_AT_TIME | Q7: Chế Đoàn Viên | R7: 0.0499
B8: Shares outstanding (Mil Shares) | C8: EQY_SH_OUT | D8: =D46/1000000 -> 31.279968 | E8: =E46/1000000 -> 31.279968 | F8: =F46/1000000 -> 131.35326 | G8: =G46/1000000 -> 137.00145 | H8: =H46/1000000 -> 191.80203 | I8: =I46/1000000 -> 191.80203 | J8: =J46/1000000 -> 191.80203 | K8: =K46/1000000 -> 191.80203 | ... N8: =N46/1000000 -> 191.80203 | Q8: Nguyễn Viết Cường | R8: 0.0476
B9: Market cap (Mil VND mn) | C9: CUR_MKT_CAP | D9: =D4*D8 -> 533949.05 | E9: =E4*E8 -> 421341.17 | F9: =F4*F8 -> 1859962.2 | G9: =G4*G8 -> 1690597.9 | H9: =H4*H8 -> 1916102.3 | Q9: Đào Phúc Trí | R9: 0.044
B10: State ownership (%) | H10: =1-78.07% -> 0.2193 | Q10: Ancla Asset Limited | R10: 0.043
B11: Foreign ownership (%) | H11: 0.0431 | Q11: Ancla Assets Limited | R11: 0.0324
B12: Free float ratio (%) | C12: EQY_FREE_FLOAT_PCT | Q12: Phạm Minh Tiến | R12: 0.0217
B13: USDVND Curncy | C13: PX_LAST | D13: 23098 | E13: 22826 | F13: 23633 | G13: 24269 | H13: 26526 | Q13: Khác | R13: 0.5839
Q14: Tổng | R14: =SUM(R5:R13) -> 0.9695
B15: 2. Welfare & Dividends
B16: Consolidated Net income | D16: ='IP_IS Raw'!E26 -> 29990231362 | E16: ='IP_IS Raw'!F26 -> 24890860314 | F16: ='IP_IS Raw'!G26 -> 26518959327 | G16: ='IP_IS Raw'!H26 -> 122574290595 | H16: ='IP_IS Raw'!I26 -> 77401200443 | Q16: Phân loại theo quốc tịch
B17: Parent company's Net income | D17: ='IP_IS Raw'!E28 -> 19793101930 | E17: ='IP_IS Raw'!F28 -> 10903987113 | F17: ='IP_IS Raw'!G28 -> 26858708163 | G17: ='IP_IS Raw'!H28 -> 125708063567 | H17: ='IP_IS Raw'!I28 -> 76561931411 | I17: =OD_IS!I21 -> 8.0780515e+10 | J17: =OD_IS!J21 -> 1.0931595e+11 | K17: =OD_IS!K21 -> 1.6130703e+11 | L17: =OD_IS!L21 -> 2.2748232e+11 | M17: =OD_IS!M21 -> 2.85354e+11 | N17: =OD_IS!N21 -> 3.0112271e+11 | Q17: Sở hữu nước ngoài | R17: 0.1227
B18: Appropriation of reserves | D18: =D19+D23 -> 0 | E18: =E19+E23 -> 0 | F18: =F19+F23 -> 0 | G18: =G19+G23 -> 0 | H18: =H19+H23 -> 0 | I18: =I19+I23 -> 0 | J18: =J19+J23 -> 0 | K18: =K19+K23 -> 0 | ... N18: =N19+N23 -> 0 | Q18: Sở hữu khác (trong nước) | R18: 0.8773
B19: Fund inside | D19: =SUM(D20:D22) -> 0 | E19: =SUM(E20:E22) -> 0 | F19: =SUM(F20:F22) -> 0 | G19: =SUM(G20:G22) -> 0 | H19: =SUM(H20:H22) -> 0 | I19: 0 | J19: 0 | K19: 0 | L19: 0 | M19: 0 | N19: 0 | Q19: Tổng | R19: =SUM(R17:R18) -> 1
B20: Investment and development funds | D20: ='IP_BS Raw'!E114 -> 0 | E20: ='IP_BS Raw'!F114 -> 0 | F20: ='IP_BS Raw'!G114 -> 0 | G20: ='IP_BS Raw'!H114 -> 0 | H20: ='IP_BS Raw'!I114 -> 0
B21: Financial reserve funds | D21: ='IP_BS Raw'!E116 -> 0 | E21: ='IP_BS Raw'!F116 -> 0 | F21: ='IP_BS Raw'!G116 -> 0 | G21: ='IP_BS Raw'!H116 -> 0 | H21: ='IP_BS Raw'!I116 -> 0
B22: Other funds | D22: ='IP_BS Raw'!E117+'IP_BS Raw'!E115 -> 0 | E22: ='IP_BS Raw'!F117+'IP_BS Raw'!F115 -> 0 | F22: ='IP_BS Raw'!G117+'IP_BS Raw'!G115 -> 0 | G22: ='IP_BS Raw'!H117+'IP_BS Raw'!H115 -> 0 | H22: ='IP_BS Raw'!I117+'IP_BS Raw'!I115 -> 0 | Q22: 2. Công ty con (9)
B23: Fund outside | D23: =SUM(D24:D25) -> 0 | E23: =SUM(E24:E25) -> 0 | F23: =SUM(F24:F25) -> 0 | G23: =SUM(G24:G25) -> 0 | H23: =SUM(H24:H25) -> 0 | I23: 0 | J23: 0 | K23: 0 | L23: 0 | M23: 0 | N23: 0 | Q23: Đơn vị | R23: Vốn điều lệ (tỷ đ) | S23: Vốn góp (tỷ đ) | T23: Tỷ lệ sở hữu (%)
B24: Bonus and welfare funds | D24: ='IP_BS Raw'!E123 -> 0 | E24: ='IP_BS Raw'!F123 -> 0 | F24: ='IP_BS Raw'!G123 -> 0 | G24: ='IP_BS Raw'!H123 -> 0 | H24: ='IP_BS Raw'!I123 -> 0 | Q24: CTCP YAG Entertainment | R24: 0 | S24: 0 | T24: 1
B25: Other funds | D25: ='IP_BS Raw'!E125+'IP_BS Raw'!E124 -> 0 | E25: ='IP_BS Raw'!F125+'IP_BS Raw'!F124 -> 0 | F25: ='IP_BS Raw'!G125+'IP_BS Raw'!G124 -> 0 | G25: ='IP_BS Raw'!H125+'IP_BS Raw'!H124 -> 0 | H25: ='IP_BS Raw'!I125+'IP_BS Raw'!I124 -> 0 | Q25: CTCP Giải trí Yeah1 | R25: 30.3 | S25: 30 | T25: 0.99
Q26: CTCP Phát triển Thương hiệu Yeah1 | R26: 15.15 | S26: 15 | T26: 0.99
B27: Cash Dividend | E27: =E29+E31 -> 31279968 | F27: =F29+F31 -> 0 | G27: =G29+G31 -> 0 | H27: =H29+H31 -> 68500727 | I27: =I29+I31 -> 68500727 | J27: =J29+J31 -> 68500727 | K27: =K29+K31 -> 68500727 | L27: =L29+L31 -> 68500727 | ... N27: =N29+N31 -> 68500727 | Q27: CTCP Giải trí Rồng | R27: 10.1 | S27: 10 | T27: 0.99
B28: % Payout ratio | E28: =E27/E17 -> 0.0028686725 | F28: =F27/F17 -> 0 | G28: =G27/G17 -> 0 | H28: =H27/H17 -> 0.00089471002 | I28: =I27/I17 -> 0.00084798577 | J28: =J27/J17 -> 0.00062663069 | K28: =K27/K17 -> 0.00042466052 | L28: =L27/L17 -> 0.0003011255 | ... N28: =N27/N17 -> 0.00022748443 | Q28: CTCP NVU | R28: 30 | S28: 29.7 | T28: 0.9
B29: 1st cash dividend | E29: =E38*E30*10 -> 31279968 | F29: =F38*F30*10 -> 0 | G29: =G38*G30*10 -> 0 | H29: =H38*H30*10 -> 68500727 | I29: =I38*I30*10 -> 68500727 | J29: =J38*J30*10 -> 68500727 | K29: =K38*K30*10 -> 68500727 | L29: =L38*L30*10 -> 68500727 | ... N29: =N38*N30*10 -> 68500727 | Q29: CTCP Thương mại Thế giới Phim | R29: 0 | S29: 0 | T29: 0.8
B30: % MP | D30: 0.05 | E30: 0.1 | F30: 0 | G30: 0 | H30: 0.05 | I30: 0.05 | J30: 0.05 | K30: 0.05 | L30: 0.05 | M30: 0.05 | N30: 0.05 | Q30: CTCP Truyền thông Trực tuyến NetLink | R30: 26.3 | S30: 19.99 | T30: 0.76
B31: 2nd cash dividend | E31: =E38*E32*10 -> 0 | F31: =F38*F32*10 -> 0 | G31: =G38*G32*10 -> 0 | H31: =H38*H32*10 -> 0 | I31: =I38*I32*10 -> 0 | J31: =J38*J32*10 -> 0 | K31: =K38*K32*10 -> 0 | L31: =L38*L32*10 -> 0 | ... N31: =N38*N32*10 -> 0 | Q31: CTCP Đầu tư và Sản xuất Phim Yeah1 | R31: 0 | S31: 0 | T31: 0.67
B32: % MP | D32: 0.05 | E32: 0 | F32: 0 | G32: 0 | H32: =G32 -> 0 | I32: =H32 -> 0 | J32: =I32 -> 0 | K32: =J32 -> 0 | L32: =K32 -> 0 | M32: =L32 -> 0 | N32: =M32 -> 0 | Q32: CTCP Truyền thông ON+ | R32: 10 | S32: 5.1 | T32: 0.51
Q33: CTCP Công nghệ Tự động Kolorlife | R33: 3.08 | S33: 1.08 | T33: 0.35 | U33: CT liên kết
B34: Stocks Dividend
B35: % MP of 1st Stocks Dividend | D35: 0 | E35: 0.1 | F35: 0.1 | G35: 0.075 | H35: 0.03 | I35: 0.05 | J35: 0.05 | K35: 0.05 | L35: 0.05 | M35: 0.05 | N35: 0.05
B36: % MP of 2nd Stocks Dividend | D36: 0 | E36: 0 | F36: 0 | G36: 0 | H36: 0 | I36: 0 | J36: 0 | K36: 0 | L36: 0 | M36: 0 | N36: 0
B37: 3. Average shares outstanding
B38: Beginning shares recording (Mil Shares) | E38: ='IP_BS Raw'!E105/10000 -> 31279968 | F38: ='IP_BS Raw'!F105/10000 -> 31279968 | G38: ='IP_BS Raw'!G105/10000 -> 131353264 | H38: ='IP_BS Raw'!H105/10000 -> 137001454 | I38: =H38 -> 137001454 | J38: =I38 -> 137001454 | K38: =J38 -> 137001454 | L38: =K38 -> 137001454 | M38: =L38 -> 137001454 | N38: =M38 -> 137001454
B39: Addition public issue (Mil Shares)
B40: - Phase 1
...

Sheet PD_Annual Breakdown
B2: Criterials | C2: Unit
D3: ='IP_BS Raw'!E2 -> 2021 | E3: ='IP_BS Raw'!F2 -> 2022 | F3: ='IP_BS Raw'!G2 -> 2023 | G3: ='IP_BS Raw'!H2 -> 2024 | H3: ='IP_BS Raw'!I2 -> 2025
B4: 1. Compose Information
B5: Revenue | C5: (VND) | D5: =SUM(D6:D8) -> 1892131002372 | E5: =SUM(E6:E8) -> 2007397494749 | F5: =SUM(F6:F8) -> 2180945411694 | G5: =SUM(G6:G8) -> 2787912700840 | H5: =SUM(H6:H8) -> 2787912700840
B6: Port Operation Services | C6: (VND) | D6: =943678041239+150369414790 -> 1094047456029 | E6: =974514896630+143274511568 -> 1117789408198 | F6: =1048833291855+134893431608+270288395868 -> 1454015119331 | G6: =1340175286046+148078142904+368565738715 -> 1856819167665 | H6: =1340175286046+148078142904+368565738715 -> 1856819167665
B7: Transportation & Freight Services | C7: (VND) | D7: =455420373236 -> 455420373236 | E7: =461503344777 -> 461503344777 | F7: =339470619876+123101930358 -> 462572550234 | G7: =359937587038+184793287841 -> 544730874879 | H7: =359937587038+184793287841 -> 544730874879
B8: Other | C8: (VND) | D8: =342663173107 -> 342663173107 | E8: =428104741774 -> 428104741774 | F8: =160061235149+104296506980 -> 264357742129 | G8: =302815612715+83547045581 -> 386362658296 | H8: =302815612715+83547045581 -> 386362658296
B9: Revenue reports | C9: (VND) | D9: ='IP_IS Raw'!E8 -> 1079507793378 | E9: ='IP_IS Raw'!F8 -> 314124306314 | F9: ='IP_IS Raw'!G8 -> 411666784900 | G9: ='IP_IS Raw'!H8 -> 1026094868172 | H9: ='IP_IS Raw'!I8 -> 1639063078002
B10: Data errors | D10: =D5-D9 -> 812623208994 | E10: =E5-E9 -> 1693273188435 | F10: =F5-F9 -> 1769278626794 | G10: =G5-G9 -> 1761817832668 | H10: =H5-H9 -> 1148849622838
B11: %YoY | C11: (%) | E11: =E5/D5-1 -> 0.060918875 | F11: =F5/E5-1 -> 0.086454186 | G11: =G5/F5-1 -> 0.27830467 | H11: =H5/G5-1 -> 0
B13: Breakdown proportion | C13: (%) | D13: =D5/D$5 -> 1 | E13: =E5/E$5 -> 1 | F13: =F5/F$5 -> 1 | G13: =G5/G$5 -> 1 | H13: =H5/H$5 -> 1
B14: =B6 -> Port Operation Services | C14: (%) | D14: =D6/D$5 -> 0.57820915 | E14: =E6/E$5 -> 0.55683511 | F14: =F6/F$5 -> 0.66669029 | G14: =G6/G$5 -> 0.66602486 | H14: =H6/H$5 -> 0.66602486
B15: =B7 -> Transportation & Freight Services | C15: (%) | D15: =D7/D$5 -> 0.24069178 | E15: =E7/E$5 -> 0.22990133 | F15: =F7/F$5 -> 0.21209726 | G15: =G7/G$5 -> 0.19539022 | H15: =H7/H$5 -> 0.19539022
B16: =B8 -> Other | C16: (%) | D16: =D8/D$5 -> 0.18109907 | E16: =E8/E$5 -> 0.21326356 | F16: =F8/F$5 -> 0.12121245 | G16: =G8/G$5 -> 0.13858492 | H16: =H8/H$5 -> 0.13858492
B18: Cost of good sold | C18: (VND) | D18: =SUM(D19:D23) -> 1.7929805e+12 | E18: =SUM(E19:E23) -> 2.8568609e+12 | F18: =SUM(F19:F23) -> 3.2104302e+12 | G18: =SUM(G19:G23) -> 3.7044612e+12 | H18: =SUM(H19:H23) -> -1424028369399
B19: Raw Materials cost | C19: (VND) | D19: =D95 -> 5.1229639e+11 | E19: =E95 -> 1.533448e+12 | F19: =F95 -> 1.6318079e+12 | G19: =G95 -> 1.6014146e+12 | H19: =H95 -> -1424028369399
B20: Labor cost | C20: (VND) | D20: =D97 -> 286828460685 | E20: =E97 -> 311382278820 | F20: =F97 -> 368910249822 | G20: =G97 -> 384763275501 | H20: =H97 -> 0
B21: Fixed A depriciation cost | C21: (VND) | D21: =D98 -> 200434357266 | E21: =E98 -> 201526522056 | F21: =F98 -> 193367525445 | G21: =G98 -> 254230428893 | H21: =H98 -> 0
B22: Outsources cost | C22: (VND) | D22: =D99 -> 513905619374 | E22: =E99 -> 562566703743 | F22: =F99 -> 808118369862 | G22: =G99 -> 1198518123985 | H22: =H99 -> 0
B23: Other cost | C23: (VND) | D23: =D100 -> 279515648242 | E23: =E100 -> 247937428273 | F23: =F100 -> 208226148927 | G23: =G100 -> 265534685439 | H23: =H100 -> 0
B25: Breakdown proportion | C25: (%) | D25: =D18/D$18 -> 1 | E25: =E18/E$18 -> 1 | F25: =F18/F$18 -> 1 | G25: =G18/G$18 -> 1 | H25: =H18/H$18 -> 1
B26: Raw Materials cost | C26: (%) | D26: =D19/D$18 -> 0.28572335 | E26: =E19/E$18 -> 0.53675976 | F26: =F19/F$18 -> 0.50828325 | G26: =G19/G$18 -> 0.43229354 | H26: =H19/H$18 -> 1
B27: Labor cost | C27: (%) | D27: =D20/D$18 -> 0.159973 | E27: =E20/E$18 -> 0.10899455 | F27: =F20/F$18 -> 0.11490991 | G27: =G20/G$18 -> 0.10386484 | H27: =H20/H$18 -> 0
B28: Fixed A depriciation cost | C28: (%) | D28: =D21/D$18 -> 0.11178837 | E28: =E21/E$18 -> 0.070541243 | F28: =F21/F$18 -> 0.060231033 | G28: =G21/G$18 -> 0.06862818 | H28: =H21/H$18 -> 0
B29: Outsources cost | C29: (%) | D29: =D22/D$18 -> 0.28662087 | E29: =E22/E$18 -> 0.19691778 | F29: =F22/F$18 -> 0.25171654 | G29: =G22/G$18 -> 0.32353373 | H29: =H22/H$18 -> 0
B30: Other cost | C30: (%) | D30: =D23/D$18 -> 0.15589442 | E30: =E23/E$18 -> 0.086786664 | F30: =F23/F$18 -> 0.064859267 | G30: =G23/G$18 -> 0.071679706 | H30: =H23/H$18 -> 0
B32: Gross profit | C32: (VND) | D32: =D5+D18 -> 3.6851115e+12 | E32: =E5+E18 -> 4.8642584e+12 | F32: =F5+F18 -> 5.3913756e+12 | G32: =G5+G18 -> 6.4923739e+12 | H32: =H5+H18 -> 1363884331441
B33: Data errors | D33: ='IP_IS Raw'!E10-'PD_Annual Breakdown'!D32 -> -3.6509864e+12 | E33: ='IP_IS Raw'!F10-'PD_Annual Breakdown'!E32 -> -4.7597797e+12 | F33: ='IP_IS Raw'!G10-'PD_Annual Breakdown'!F32 -> -5.2761898e+12 | G33: ='IP_IS Raw'!H10-'PD_Annual Breakdown'!G32 -> -6.3215227e+12 | H33: ='IP_IS Raw'!I10-'PD_Annual Breakdown'!H32 -> -1148849622838
B34: %YoY | C34: (%) | E34: =E32/D32-1 -> 0.31997592 | F34: =F32/E32-1 -> 0.10836537 | G34: =G32/F32-1 -> 0.20421472 | H34: =H32/G32-1 -> -0.78992517
B36: Gross Profit Margin | C36: (%) | D36: =D32/D5 -> 1.9475985 | E36: =E32/E5 -> 2.4231665 | F36: =F32/F5 -> 2.472036 | G36: =G32/G5 -> 2.3287579 | H36: =H32/H5 -> 0.48921343
B38: Selling expenses | C38: (VND) | D38: ='IP_IS Raw'!E15 -> -86766850424 | E38: ='IP_IS Raw'!F15 -> -20658752305 | F38: ='IP_IS Raw'!G15 -> -14260496293 | G38: ='IP_IS Raw'!H15 -> -26239808550 | H38: ='IP_IS Raw'!I15 -> -39335239608
B39: As a revenue | C39: (%) | D39: =-D38/D5 -> 0.045856682 | E39: =-E38/E5 -> 0.010291311 | F39: =-F38/F5 -> 0.0065386764 | G39: =-G38/G5 -> 0.0094119907 | H39: =-H38/H5 -> 0.014109208
B41: G&A expenses | C41: (VND) | D41: ='IP_IS Raw'!E16 -> -211115902487 | E41: ='IP_IS Raw'!F16 -> -93384172422 | F41: ='IP_IS Raw'!G16 -> -66900478155 | G41: ='IP_IS Raw'!H16 -> -151633232794 | H41: ='IP_IS Raw'!I16 -> -167762629718
B42: As a revenue | C42: (%) | D42: =-D41/D5 -> 0.11157573 | E42: =-E41/E5 -> 0.04652002 | F42: =-F41/F5 -> 0.03067499 | G42: =-G41/G5 -> 0.05438952 | H42: =-H41/H5 -> 0.060174994
B44: Breakdown operation expenses | C44: (%) | D44: =(D18+D38+D41)/(D$18+D$38+D$41) -> 1 | E44: =(E18+E38+E41)/(E$18+E$38+E$41) -> 1 | F44: =(F18+F38+F41)/(F$18+F$38+F$41) -> 1 | G44: =(G18+G38+G41)/(G$18+G$38+G$41) -> 1 | H44: =(H18+H38+H41)/(H$18+H$38+H$41) -> 1
B45: Total COGS | C45: (%) | D45: =(D18)/(D$18+D$38+D$41) -> 1.1992397 | E45: =(E18)/(E$18+E$38+E$41) -> 1.0415787 | F45: =(F18)/(F$18+F$38+F$41) -> 1.0259361 | G45: =(G18)/(G$18+G$38+G$41) -> 1.0504377 | H45: =(H18)/(H$18+H$38+H$41) -> 0.87303382
B46: Selling Expenses | C46: (%) | D46: =(D38)/(D$18+D$38+D$41) -> -0.058034233 | E46: =(E38)/(E$18+E$38+E$41) -> -0.0075319443 | F46: =(F38)/(F$18+F$38+F$41) -> -0.0045571331 | G46: =(G38)/(G$18+G$38+G$41) -> -0.0074405651 | H46: =(H38)/(H$18+H$38+H$41) -> 0.024115386
B47: GS&A Expenses | C47: (%) | D47: =(D41)/(D$18+D$38+D$41) -> -0.14120542 | E47: =(E41)/(E$18+E$38+E$41) -> -0.034046799 | F47: =(F41)/(F$18+F$38+F$41) -> -0.021378946 | G47: =(G41)/(G$18+G$38+G$41) -> -0.042997148 | H47: =(H41)/(H$18+H$38+H$41) -> 0.10285079
B48: Raw Materials cost | C48: (%) | D48: =(D103)/(D$18+D$38+D$41) -> 0.092634417 | E48: =(E103)/(E$18+E$38+E$41) -> 0.076505383 | F48: =(F103)/(F$18+F$38+F$41) -> 0.055870322 | G48: =(G103)/(G$18+G$38+G$41) -> 0.05013512 | H48: =(H103)/(H$18+H$38+H$41) -> 0
B49: Labor cost | C49: (%) | D49: =(D104)/(D$18+D$38+D$41) -> 0.19184596 | E49: =(E104)/(E$18+E$38+E$41) -> 0.11352641 | F49: =(F104)/(F$18+F$38+F$41) -> 0.11789022 | G49: =(G104)/(G$18+G$38+G$41) -> 0.10910355 | H49: =(H104)/(H$18+H$38+H$41) -> 0
...

Sheet PD_Operation
B2: PD_Operation — Forecast Drivers | G2: 45291 | H2: =DATE(YEAR(G2),MONTH(G2)+13,0) -> 45657 | I2: =DATE(YEAR(H2),MONTH(H2)+13,0) -> 46022 | J2: =DATE(YEAR(I2),MONTH(I2)+13,0) -> 46387 | K2: =DATE(YEAR(J2),MONTH(J2)+13,0) -> 46752 | L2: =DATE(YEAR(K2),MONTH(K2)+13,0) -> 47118 | M2: =DATE(YEAR(L2),MONTH(L2)+13,0) -> 47483 | N2: =DATE(YEAR(M2),MONTH(M2)+13,0) -> 47848
B3: Item | C3: Unit | D3: =OD_IS!D3 -> 2021 | E3: =OD_IS!E3 -> 2022 | F3: =OD_IS!F3 -> 2023 | G3: =OD_IS!G3 -> 2024 | H3: =OD_IS!H3 -> 2025 | I3: =OD_IS!I3 -> 2026 | J3: =OD_IS!J3 -> 2027 | K3: =OD_IS!K3 -> 2028 | ... N3: =OD_IS!N3 -> 2031
B4: 1. Revenue
B5: Income Statement Drivers | C5: (Thoudsan Units)
B6: Revenue | C6: (VND) | D6: =OD_IS!D4 -> 1079507793378 | E6: =OD_IS!E4 -> 314124306314 | F6: =OD_IS!F4 -> 411666784900 | G6: =OD_IS!G4 -> 1026094868172 | H6: =OD_IS!H4 -> 1639063078002 | I6: =H6*(1+I7) -> 2.130782e+12 | J6: =I6*(1+J7) -> 2.599554e+12 | K6: =J6*(1+K7) -> 2.9894871e+12 | L6: =K6*(1+L7) -> 3.3183307e+12 | M6: =L6*(1+M7) -> 3.5837972e+12 | N6: =M6*(1+N7) -> 3.7629871e+12
B7: Revenue growth % | E7: =E6/D6-1 -> -0.70901154 | F7: =F6/E6-1 -> 0.31052191 | G7: =G6/F6-1 -> 1.4925374 | H7: =H6/G6-1 -> 0.59737967 | I7: 0.3 | J7: 0.22 | K7: 0.15 | L7: 0.11 | M7: 0.08 | N7: 0.05
B8: COGS % of revenue | C8: (%) | D8: =-OD_IS!D5/OD_IS!D4 -> 0.96838829 | E8: =-OD_IS!E5/OD_IS!E4 -> 0.667397 | F8: =-OD_IS!F5/OD_IS!F4 -> 0.72019644 | G8: =-OD_IS!G5/OD_IS!G4 -> 0.83349379 | H8: =-OD_IS!H5/OD_IS!H4 -> 0.86880633 | I8: 0.87 | J8: 0.86 | K8: 0.84 | L8: 0.82 | M8: 0.81 | N8: 0.81
B9: Selling expenses % of revenue | C9: (%) | D9: =-OD_IS!D7/OD_IS!D4 -> 0.080376308 | E9: =-OD_IS!E7/OD_IS!E4 -> 0.065766169 | F9: =-OD_IS!F7/OD_IS!F4 -> 0.034640872 | G9: =-OD_IS!G7/OD_IS!G4 -> 0.025572498 | H9: =-OD_IS!H7/OD_IS!H4 -> 0.023998612 | I9: 0.025 | J9: 0.025 | K9: 0.025 | L9: 0.025 | M9: 0.025 | N9: 0.025
B10: G&A expenses % of revenue | C10: (%) | D10: =-OD_IS!D8/OD_IS!D4 -> 0.19556682 | E10: =-OD_IS!E8/OD_IS!E4 -> 0.29728413 | F10: =-OD_IS!F8/OD_IS!F4 -> 0.16251124 | G10: =-OD_IS!G8/OD_IS!G4 -> 0.14777701 | H10: =-OD_IS!H8/OD_IS!H4 -> 0.10235276 | I10: 0.1 | J10: 0.098 | K10: 0.095 | L10: 0.093 | M10: 0.09 | N10: 0.09
B11: D&A (VND bn) — fixed asset-light | C11: (VND bn) | D11: =OD_CF!D6/OD_IS!D4 -> 0.18567199 | E11: =OD_CF!E6/OD_IS!E4 -> 0.64155023 | F11: =OD_CF!F6/OD_IS!F4 -> 0.46971855 | G11: =OD_CF!G6/OD_IS!G4 -> 0.24776503 | H11: =OD_CF!H6/OD_IS!H4 -> 0 | I11: 250 | J11: =I11*1.05 -> 262.5 | K11: =J11*1.05 -> 275.625 | L11: =K11*1.05 -> 289.40625 | M11: =L11*1.05 -> 303.87656 | N11: =M11*1.05 -> 319.07039
B12: Financial income % of revenue | C12: (%) | D12: =OD_IS!D10/OD_IS!D4 -> 0.39263204 | E12: =OD_IS!E10/OD_IS!E4 -> 0.15070591 | F12: =OD_IS!F10/OD_IS!F4 -> 0.10587787 | G12: =OD_IS!G10/OD_IS!G4 -> 0.18702609 | H12: =OD_IS!H10/OD_IS!H4 -> 0.073425596 | I12: 0.06 | J12: 0.05 | K12: 0.04 | L12: 0.035 | M12: 0.035 | N12: 0.035
B13: Tax rate | C13: (%) | D13: =-OD_IS!D19/OD_IS!D16 -> 0.69496305 | E13: =-OD_IS!E19/OD_IS!E16 -> 0.1391716 | F13: =-OD_IS!F19/OD_IS!F16 -> 0.083154087 | G13: =-OD_IS!G19/OD_IS!G16 -> -0.10081374 | H13: =-OD_IS!H19/OD_IS!H16 -> 0.17342221 | I13: =OD_Valuation!$C$11 -> 0.2 | J13: =OD_Valuation!$C$11 -> 0.2 | K13: =OD_Valuation!$C$11 -> 0.2 | L13: =OD_Valuation!$C$11 -> 0.2 | M13: =OD_Valuation!$C$11 -> 0.2 | N13: =OD_Valuation!$C$11 -> 0.2
B14: % Selling volume/ Capacity | C14: (%)
B15: Balance Sheet / WC Drivers | C15: (%)
B16: Days in AR | C16: (Days) | D16: =365*OD_BS!D8/OD_IS!D4 -> 358.25449 | E16: =365*OD_BS!E8/OD_IS!E4 -> 628.96559 | F16: =365*OD_BS!F8/OD_IS!F4 -> 749.56091 | G16: =365*OD_BS!G8/OD_IS!G4 -> 391.97605 | H16: =365*OD_BS!H8/OD_IS!H4 -> 290.65262 | I16: 120 | J16: 100 | K16: 90 | L16: 80 | M16: 80 | N16: 80
B17: Days in Inventory | C17: (Days) | D17: =-365*OD_BS!D9/OD_IS!D5 -> 10.727246 | E17: =-365*OD_BS!E9/OD_IS!E5 -> 27.005171 | F17: =-365*OD_BS!F9/OD_IS!F5 -> 35.9097 | G17: =-365*OD_BS!G9/OD_IS!G5 -> 17.414652 | H17: =-365*OD_BS!H9/OD_IS!H5 -> 25.081931 | I17: =AVERAGE($G17:$H17) -> 21.248291 | J17: =AVERAGE($G17:$H17) -> 21.248291 | K17: =AVERAGE($G17:$H17) -> 21.248291 | L17: =AVERAGE($G17:$H17) -> 21.248291 | M17: =AVERAGE($G17:$H17) -> 21.248291 | N17: =AVERAGE($G17:$H17) -> 21.248291
B18: Days in AP | C18: (Days) | D18: =-365*OD_BS!D20/OD_IS!D5 -> 30.49002 | E18: =-365*OD_BS!E20/OD_IS!E5 -> 144.82228 | F18: =-365*OD_BS!F20/OD_IS!F5 -> 120.83705 | G18: =-365*OD_BS!G20/OD_IS!G5 -> 58.720838 | H18: =-365*OD_BS!H20/OD_IS!H5 -> 38.214938 | I18: =$H18 -> 38.214938 | J18: =$H18 -> 38.214938 | K18: =$H18 -> 38.214938 | L18: =$H18 -> 38.214938 | M18: =$H18 -> 38.214938 | N18: =$H18 -> 38.214938
B19: Other Current Asset % of revenue | C19: (%) | D19: =OD_BS!D10/OD_IS!D4 -> 0.032494183 | E19: =OD_BS!E10/OD_IS!E4 -> 0.12678959 | F19: =OD_BS!F10/OD_IS!F4 -> 0.15639914 | G19: =OD_BS!G10/OD_IS!G4 -> 0.024467047 | H19: =OD_BS!H10/OD_IS!H4 -> 0.0090024146 | I19: =AVERAGE($G19:$H19) -> 0.016734731 | J19: =AVERAGE($G19:$H19) -> 0.016734731 | K19: =AVERAGE($G19:$H19) -> 0.016734731 | L19: =AVERAGE($G19:$H19) -> 0.016734731 | M19: =AVERAGE($G19:$H19) -> 0.016734731 | N19: =AVERAGE($G19:$H19) -> 0.016734731
B20: Other Current Liab % of revenue | C20: (%) | D20: =OD_BS!D22/OD_IS!D4 -> 0.17175569 | E20: =OD_BS!E22/OD_IS!E4 -> 0.43930455 | F20: =OD_BS!F22/OD_IS!F4 -> 0.33793801 | G20: =OD_BS!G22/OD_IS!G4 -> 0.29045091 | H20: =OD_BS!H22/OD_IS!H4 -> 0.10820902 | I20: =AVERAGE($G20:$H20) -> 0.19932996 | J20: =AVERAGE($G20:$H20) -> 0.19932996 | K20: =AVERAGE($G20:$H20) -> 0.19932996 | L20: =AVERAGE($G20:$H20) -> 0.19932996 | M20: =AVERAGE($G20:$H20) -> 0.19932996 | N20: =AVERAGE($G20:$H20) -> 0.19932996
B21: CapEx % of revenue | C21: (%) | D21: =-OD_CF!D10/OD_IS!D4 -> 0.0026974283 | E21: =-OD_CF!E10/OD_IS!E4 -> 0.00083435412 | F21: =-OD_CF!F10/OD_IS!F4 -> 0.20683059 | G21: =-OD_CF!G10/OD_IS!G4 -> 0.53887787 | H21: =-OD_CF!H10/OD_IS!H4 -> 0.059924103 | I21: 0.06 | J21: 0.05 | K21: 0.04 | L21: 0.04 | M21: 0.04 | N21: 0.04
B22: %YoY growth | C22: (%)
B23: Financing Drivers
B24: Short-term debt (hold flat) | C24: (VND) | D24: =OD_BS!D21 -> 130796216812 | E24: =OD_BS!E21 -> 94317807400 | F24: =OD_BS!F21 -> 171352690912 | G24: =OD_BS!G21 -> 527364096445 | H24: =OD_BS!H21 -> 304271257481 | I24: =$H24 -> 304271257481 | J24: =$H24 -> 304271257481 | K24: =$H24 -> 304271257481 | L24: =$H24 -> 304271257481 | M24: =$H24 -> 304271257481 | N24: =$H24 -> 304271257481
B25: Long-term debt (hold flat) | C25: (VND) | D25: =OD_BS!D24 -> 71000000000 | E25: =OD_BS!E24 -> 1000000000 | F25: =OD_BS!F24 -> 39014432856 | G25: =OD_BS!G24 -> 50006060793 | H25: =OD_BS!H24 -> 36866802037 | I25: =$H25 -> 36866802037 | J25: =$H25 -> 36866802037 | K25: =$H25 -> 36866802037 | L25: =$H25 -> 36866802037 | M25: =$H25 -> 36866802037 | N25: =$H25 -> 36866802037
B26: Dividend payout ratio | C26: (%) | D26: =IFERROR(-OD_CF!D15/OD_IS!D21,0) -> 0 | E26: =IFERROR(-OD_CF!E15/OD_IS!E21,0) -> 0 | F26: =IFERROR(-OD_CF!F15/OD_IS!F21,0) -> 0 | G26: =IFERROR(-OD_CF!G15/OD_IS!G21,0) -> 0 | H26: =IFERROR(-OD_CF!H15/OD_IS!H21,0) -> 0.015584581 | I26: 0 | J26: 0 | K26: 0.05 | L26: 0.1 | M26: 0.15 | N26: 0.2
B27: %YoY growth | C27: (%)
B28: =B10 -> G&A expenses % of revenue | C28: (VND)
B29: %YoY growth | C29: (%)
B30: =B13 -> Tax rate | C30: (VND)
B31: %YoY growth | C31: (%)
B32: %CAGR in the 2018 - 2023 | C32: (%)
B34: 2. COGS
B35: A. Summary data
B36: Absolute data for COGS | C36: (VND)
B37: Raw Materials cost | C37: (VND)
B38: Labor cost | C38: (VND)
B39: Fixed A depriciation cost | C39: (VND)
B40: Outsources cost and other cost | C40: (VND)
B42: Relative data for COGS | C42: (VND)
B43: Raw Materials cost | C43: (VND)
...

Sheet IPc_WACC and Beta
A1: 1. Input data | K1: 2. Process data | O1: 3. Assumptions
A2: a. Trading data | H2: b. Other data and Process Raw data | K2: a. ERP
A3: Date | B3: VN-Index | D3: YEG | H3: Tickers | I3: Data | K3: Method 1 | L3: ERP VN = ERP US + CRP VN (CDS, có điều chỉnh) | O3: Tickers | P3: Data
B4: Last Price | C4: Change | D4: Last Price | E4: Change | H4: ERP US (Damodaran) | I4: 0.04225 | L4: ERP US | M4: =I4 -> 0.04225 | O4: Risk free rate | P4: 0.042
B5: PX_LAST | C5: (%) | D5: PX_LAST | E5: (%) | H5: Chênh lệch CDS (Damodaran) | I5: 0.0126 | L5: Chên lệch CDS | M5: =I5 -> 0.0126 | O5: Beta (U) | P5: =I9 -> 0.82336143
A6: 46136 | B6: 1853.29 | C6: =(B6-B7)/B7 -> -0.0091265853 | D6: 9990 | E6: =(D6-D7)/D7 -> 0.001002004 | H6: Chênh lệch Moody's Rating (Damodaran) | I6: 0.0283 | L6: Hệ số điều chỉnh | M6: =I11 -> 1.3 | O6: ERP VN | P6: =M16 -> 0.08112
A7: 46135 | B7: 1870.36 | C7: =(B7-B8)/B8 -> 0.0070317127 | D7: 9980 | E7: =(D7-D8)/D8 -> -0.021568627 | H7: ERP VN | I7: 0.0832 | L7: ERP VN | M7: =M4+M5*M6 -> 0.05863 | O7: Current Cost of Equity (Ke) | P7: =P4+P5*P6 -> 0.10879108
A8: 46134 | B8: 1857.3 | C8: =(B8-B9)/B9 -> 0.012991688 | D8: 10200 | E8: =(D8-D9)/D9 -> 0.0049261084 | H8: Thuế suất thuế TNDN | I8: 0.2 | O8: Current Cost of Debt | P8: =OD_IS!H57 -> 0.075923967
A9: 46133 | B9: 1833.48 | C9: =(B9-B10)/B10 -> -0.0019759296 | D9: 10150 | E9: =(D9-D10)/D10 -> -0.0097560976 | H9: Hệ số Beta YEG (SLOPE 1Y) | I9: =SLOPE(E6:E250,C6:C250) -> 0.82336143 | K9: Method 2 | L9: ERP VN = ERP US + CRP VN (Moody's, có điều chỉnh) | O9: Tax rate | P9: 0.2
A10: 46132 | B10: 1837.11 | C10: =(B10-B11)/B11 -> 0.010973107 | D10: 10250 | E10: =(D10-D11)/D11 -> -0.0048543689 | H10: Hệ số D/E in 2024 | I10: =('IP_BS Raw'!H83+'IP_BS Raw'!H96)/'IP_BS Raw'!H103 -> 0.38494462 | L10: ERP US | M10: =I4 -> 0.04225 | O10: Current Cost of Debt after tax (Kd) | P10: =P8*(1-P9) -> 0.060739173
A11: 46129 | B11: 1817.17 | C11: =(B11-B12)/B12 -> -0.001461675 | D11: 10300 | E11: =(D11-D12)/D12 -> 0.0048780488 | H11: Hệ số | I11: 1.3 | L11: Chên lệch Moody's Rating | M11: =I6 -> 0.0283 | O11: D/E | P11: =I10 -> 0.38494462
A12: 46128 | B12: 1819.83 | C12: =(B12-B13)/B13 -> 0.010651709 | D12: 10250 | E12: =(D12-D13)/D13 -> -0.0048543689 | H12: Standard Deviation of VN-Index | I12: =_xlfn.STDEV.S(C6:C250) -> 0.013145251 | L12: Hệ số điều chỉnh | M12: =I11 -> 1.3 | O12: D/(D+E) | P12: =P11/(1+P11) -> 0.27794947
A13: 46127 | B13: 1800.65 | C13: =(B13-B14)/B14 -> 0.014079351 | D13: 10300 | E13: =(D13-D14)/D14 -> -0.019047619 | L13: ERP VN | M13: =M10+M11*M12 -> 0.07904 | O13: Current WACC | P13: =P7*(1-P12)+P12*P10 -> 0.095435078
A14: 46126 | B14: 1775.65 | C14: =(B14-B15)/B15 -> 0.0094885614 | D14: 10500 | E14: =(D14-D15)/D15 -> -0.018691589
A15: 46125 | B15: 1758.96 | C15: =(B15-B16)/B16 -> 0.00512 | D15: 10700 | E15: =(D15-D16)/D16 -> 0.033816425 | K15: Average | L15: MAX of two methods | M15: =MAX(M7,M13) -> 0.07904
A16: 46122 | B16: 1750 | C16: =(B16-B17)/B17 -> 0.0076698068 | D16: 10350 | E16: =(D16-D17)/D17 -> 0.035 | K16: Final | L16: Average of MAX & ERP VN (Damodaran) | M16: =AVERAGE(M15,I7) -> 0.08112
A17: 46121 | B17: 1736.68 | C17: =(B17-B18)/B18 -> -0.011311947 | D17: 10000 | E17: =(D17-D18)/D18 -> -0.0099009901
A18: 46120 | B18: 1756.55 | C18: =(B18-B19)/B19 -> 0.047098728 | D18: 10100 | E18: =(D18-D19)/D19 -> 0.026422764
A19: 46119 | B19: 1677.54 | C19: =(B19-B20)/B20 -> 0.0015223971 | D19: 9840 | E19: =(D19-D20)/D20 -> 0.0051072523
A20: 46118 | B20: 1674.99 | C20: =(B20-B21)/B21 -> -0.0053739816 | D20: 9790 | E20: =(D20-D21)/D21 -> -0.015090543
A21: 46115 | B21: 1684.04 | C21: =(B21-B22)/B22 -> -0.0063605575 | D21: 9940 | E21: =(D21-D22)/D22 -> -0.006
A22: 46114 | B22: 1694.82 | C22: =(B22-B23)/B23 -> -0.0047623801 | D22: 10000 | E22: =(D22-D23)/D23 -> -0.014778325
A23: 46113 | B23: 1702.93 | C23: =(B23-B24)/B24 -> 0.016984276 | D23: 10150 | E23: =(D23-D24)/D24 -> 0.015
A24: 46112 | B24: 1674.49 | C24: =(B24-B25)/B25 -> 0.007187797 | D24: 10000 | E24: =(D24-D25)/D25 -> 0.0050251256
A25: 46111 | B25: 1662.54 | C25: =(B25-B26)/B26 -> -0.006133429 | D25: 9950 | E25: =(D25-D26)/D26 -> -0.0099502488
A26: 46108 | B26: 1672.8 | C26: =(B26-B27)/B27 -> 0.017128473 | D26: 10050 | E26: =(D26-D27)/D27 -> 0.005
A27: 46107 | B27: 1644.63 | C27: =(B27-B28)/B28 -> -0.0081775912 | D27: 10000 | E27: =(D27-D28)/D28 -> -0.0099009901
A28: 46106 | B28: 1658.19 | C28: =(B28-B29)/B29 -> 0.026889278 | D28: 10100 | E28: =(D28-D29)/D29 -> 0.017119839
... A250: 45783 | B250: 1241.95 | C250: =(B250-B251)/B251 -> 0.0015321963 | D250: 11750 | E250: =(D250-D251)/D251 -> -0.0042372881
A251: 45782 | B251: 1240.05 | D251: 11800

Sheet OD_BS
G2: 45291 | H2: =DATE(YEAR(G2),MONTH(G2)+13,0) -> 45657 | I2: =DATE(YEAR(H2),MONTH(H2)+13,0) -> 46022 | J2: =DATE(YEAR(I2),MONTH(I2)+13,0) -> 46387 | K2: =DATE(YEAR(J2),MONTH(J2)+13,0) -> 46752 | L2: =DATE(YEAR(K2),MONTH(K2)+13,0) -> 47118 | M2: =DATE(YEAR(L2),MONTH(L2)+13,0) -> 47483 | N2: =DATE(YEAR(M2),MONTH(M2)+13,0) -> 47848
B3: Items | C3: Unit | D3: ='IP_BS Raw'!E2 -> 2021 | E3: =D3+1 -> 2022 | F3: =E3+1 -> 2023 | G3: =F3+1 -> 2024 | H3: =G3+1 -> 2025 | I3: =H3+1 -> 2026 | J3: =I3+1 -> 2027 | K3: =J3+1 -> 2028 | L3: =K3+1 -> 2029 | ... N3: =M3+1 -> 2031
B4: Total Asset | C4: (VNDbn) | D4: =D5+D11 -> 1388467146198 | E4: =E5+E11 -> 1311932297572 | F4: =F5+F11 -> 1891225676406 | G4: =G5+G11 -> 2814732850457 | H4: =H5+H11 -> 3066234160063 | I4: =I5+I11 -> 2.3703758e+12 | J4: =J5+J11 -> 2.2796022e+12 | K4: =K5+K11 -> 2.1710505e+12 | ... N4: =N5+N11 -> 1.8171291e+12
B5: Current Asset | C5: (VND bn) | D5: =SUM(D6:D10) -> 1134580036184 | E5: =SUM(E6:E10) -> 623158641225 | F5: =SUM(F6:F10) -> 947639699363 | G5: =SUM(G6:G10) -> 1305306889451 | H5: =SUM(H6:H10) -> 1870935494083 | I5: =SUM(I6:I10) -> 1.2972302e+12 | J5: =SUM(J6:J10) -> 1.3389789e+12 | K5: =SUM(K6:K10) -> 1.3864727e+12 | ... N5: =SUM(N6:N10) -> 1.5183e+12
B6: Cash & Equivalents | C6: (VND bn) | D6: ='IP_BS Raw'!E7 -> 4321225874 | E6: ='IP_BS Raw'!F7 -> 26473013864 | F6: ='IP_BS Raw'!G7 -> 8461339357 | G6: ='IP_BS Raw'!H7 -> 136236074178 | H6: ='IP_BS Raw'!I7 -> 288524181242 | I6: =H6 -> 288524181242 | J6: =I6 -> 288524181242 | K6: =J6 -> 288524181242 | L6: =K6 -> 288524181242 | M6: =L6 -> 288524181242 | N6: =M6 -> 288524181242
B7: Short-term investments | C7: (VND bn) | D7: ='IP_BS Raw'!E10 -> 4900000000 | E7: ='IP_BS Raw'!F10 -> 50000000 | F7: ='IP_BS Raw'!G10 -> 230000000 | G7: ='IP_BS Raw'!H10 -> 1230000000 | H7: ='IP_BS Raw'!I10 -> 164600000000 | I7: =H7 -> 164600000000 | J7: =I7 -> 164600000000 | K7: =J7 -> 164600000000 | L7: =K7 -> 164600000000 | M7: =L7 -> 164600000000 | N7: =M7 -> 164600000000
B8: Account Receivables | C8: (VND bn) | D8: ='IP_BS Raw'!E14 -> 1059557585612 | E8: ='IP_BS Raw'!F14 -> 541296932112 | F8: ='IP_BS Raw'!G14 -> 845395421575 | G8: ='IP_BS Raw'!H14 -> 1101930451740 | H8: ='IP_BS Raw'!I14 -> 1305199947643 | I8: =PD_Operation!I16/365*OD_IS!I4 -> 7.0053107e+11 | J8: =PD_Operation!J16/365*OD_IS!J4 -> 7.1220659e+11 | K8: =PD_Operation!K16/365*OD_IS!K4 -> 7.3713382e+11 | L8: =PD_Operation!L16/365*OD_IS!L4 -> 7.2730537e+11 | M8: =PD_Operation!M16/365*OD_IS!M4 -> 7.854898e+11 | N8: =PD_Operation!N16/365*OD_IS!N4 -> 8.2476429e+11
B9: Inventories | C9: (VND bn) | D9: ='IP_BS Raw'!E23 -> 30723500694 | E9: ='IP_BS Raw'!F23 -> 15511002401 | F9: ='IP_BS Raw'!G23 -> 29168608393 | G9: ='IP_BS Raw'!H23 -> 40804852414 | H9: ='IP_BS Raw'!I23 -> 97855839839 | I9: =PD_Operation!I17/365*(-OD_IS!I5) -> 1.0791689e+11 | J9: =PD_Operation!J17/365*(-OD_IS!J5) -> 1.3014529e+11 | K9: =PD_Operation!K17/365*(-OD_IS!K5) -> 1.4618645e+11 | L9: =PD_Operation!L17/365*(-OD_IS!L5) -> 1.5840346e+11 | M9: =PD_Operation!M17/365*(-OD_IS!M5) -> 1.6898945e+11 | N9: =PD_Operation!N17/365*(-OD_IS!N5) -> 1.7743892e+11
